 Container notaai--redis-1  Running
Traceback (most recent call last):
  File "<string>", line 1, in <module>
  File "/app/config.py", line 43, in <module>
    settings = Config()
               ^^^^^^^^
  File "/usr/local/lib/python3.11/site-packages/pydantic_settings/main.py", line 176, in __init__
    super().__init__(
  File "/usr/local/lib/python3.11/site-packages/pydantic/main.py", line 253, in __init__
    validated_self = self.__pydantic_validator__.validate_python(data, self_instance=self)
                     ^^^^^^^^^^^^^^^^^^^^^^^^^^^^^^^^^^^^^^^^^^^^^^^^^^^^^^^^^^^^^^^^^^^^^
pydantic_core._pydantic_core.ValidationError: 6 validation errors for Config
openai_api_key
  Field required [type=missing, input_value={}, input_type=dict]
    For further information visit https://errors.pydantic.dev/2.11/v/missing
telegram_token
  Field required [type=missing, input_value={}, input_type=dict]
    For further information visit https://errors.pydantic.dev/2.11/v/missing
syrve_server_url
  Field required [type=missing, input_value={}, input_type=dict]
    For further information visit https://errors.pydantic.dev/2.11/v/missing
syrve_login
  Field required [type=missing, input_value={}, input_type=dict]
    For further information visit https://errors.pydantic.dev/2.11/v/missing
syrve_password
  Field required [type=missing, input_value={}, input_type=dict]
    For further information visit https://errors.pydantic.dev/2.11/v/missing
default_store_id
  Field required [type=missing, input_value={}, input_type=dict]
    For further information visit https://errors.pydantic.dev/2.11/v/missing

